Watching for file changes with StatReloader
System check identified some issues:

WARNINGS:
?: (ckeditor.W001) django-ckeditor bundles CKEditor 4.22.1 which isn't supported anymore and which does have unfixed security issues, see for example https://ckeditor.com/cke4/release/CKEditor-4.24.0-LTS . You should consider strongly switching to a different editor (maybe CKEditor 5 respectively django-ckeditor-5 after checking whether the CKEditor 5 license terms work for you) or switch to the non-free CKEditor 4 LTS package. See https://ckeditor.com/ckeditor-4-support/ for more on this. (Note! This notice has been added by the django-ckeditor developers and we are not affiliated with CKSource and were not involved in the licensing change, so please refrain from complaining to us. Thanks.)

System check identified 1 issue (0 silenced).
[26/May/2025 16:10:34] "GET / HTTP/1.1" 200 7564
[26/May/2025 16:23:27] "GET / HTTP/1.1" 200 7564
[26/May/2025 16:23:29] "GET / HTTP/1.1" 200 7564
Watching for file changes with StatReloader
Exception in thread django-main-thread:
Traceback (most recent call last):
  File "/usr/lib/python3.10/threading.py", line 1016, in _bootstrap_inner
    self.run()
  File "/usr/lib/python3.10/threading.py", line 953, in run
    self._target(*self._args, **self._kwargs)
  File "/home/administrator/.local/lib/python3.10/site-packages/django/utils/autoreload.py", line 64, in wrapper
    fn(*args, **kwargs)
  File "/home/administrator/.local/lib/python3.10/site-packages/django/core/management/commands/runserver.py", line 124, in inner_run
    autoreload.raise_last_exception()
  File "/home/administrator/.local/lib/python3.10/site-packages/django/utils/autoreload.py", line 86, in raise_last_exception
    raise _exception[1]
  File "/home/administrator/.local/lib/python3.10/site-packages/django/core/management/__init__.py", line 394, in execute
    autoreload.check_errors(django.setup)()
  File "/home/administrator/.local/lib/python3.10/site-packages/django/utils/autoreload.py", line 64, in wrapper
    fn(*args, **kwargs)
  File "/home/administrator/.local/lib/python3.10/site-packages/django/__init__.py", line 24, in setup
    apps.populate(settings.INSTALLED_APPS)
  File "/home/administrator/.local/lib/python3.10/site-packages/django/apps/registry.py", line 91, in populate
    app_config = AppConfig.create(entry)
  File "/home/administrator/.local/lib/python3.10/site-packages/django/apps/config.py", line 193, in create
    import_module(entry)
  File "/usr/lib/python3.10/importlib/__init__.py", line 126, in import_module
    return _bootstrap._gcd_import(name[level:], package, level)
  File "<frozen importlib._bootstrap>", line 1050, in _gcd_import
  File "<frozen importlib._bootstrap>", line 1027, in _find_and_load
  File "<frozen importlib._bootstrap>", line 1004, in _find_and_load_unlocked
ModuleNotFoundError: No module named 'crispy_forms'
Traceback (most recent call last):
  File "/home/administrator/.local/lib/python3.10/site-packages/django/template/utils.py", line 69, in __getitem__
    return self._engines[alias]
KeyError: 'django'

During handling of the above exception, another exception occurred:

Traceback (most recent call last):
  File "/home/administrator/.local/lib/python3.10/site-packages/django/template/library.py", line 477, in import_library
    module = import_module(name)
  File "/usr/lib/python3.10/importlib/__init__.py", line 126, in import_module
    return _bootstrap._gcd_import(name[level:], package, level)
  File "<frozen importlib._bootstrap>", line 1050, in _gcd_import
  File "<frozen importlib._bootstrap>", line 1027, in _find_and_load
  File "<frozen importlib._bootstrap>", line 1006, in _find_and_load_unlocked
  File "<frozen importlib._bootstrap>", line 688, in _load_unlocked
  File "<frozen importlib._bootstrap_external>", line 883, in exec_module
  File "<frozen importlib._bootstrap>", line 241, in _call_with_frames_removed
  File "/home/administrator/Documents/Compass_Project/compass/templatetags/import_export_tags.py", line 1, in <module>
    from diff_match_patch import diff_match_patch
ModuleNotFoundError: No module named 'diff_match_patch'

During handling of the above exception, another exception occurred:

Traceback (most recent call last):
  File "/home/administrator/Documents/Compass_Project/compass/manage.py", line 22, in <module>
    main()
  File "/home/administrator/Documents/Compass_Project/compass/manage.py", line 18, in main
    execute_from_command_line(sys.argv)
  File "/home/administrator/.local/lib/python3.10/site-packages/django/core/management/__init__.py", line 442, in execute_from_command_line
    utility.execute()
  File "/home/administrator/.local/lib/python3.10/site-packages/django/core/management/__init__.py", line 436, in execute
    self.fetch_command(subcommand).run_from_argv(self.argv)
  File "/home/administrator/.local/lib/python3.10/site-packages/django/core/management/base.py", line 416, in run_from_argv
    self.execute(*args, **cmd_options)
  File "/home/administrator/.local/lib/python3.10/site-packages/django/core/management/commands/runserver.py", line 69, in execute
    super().execute(*args, **options)
  File "/home/administrator/.local/lib/python3.10/site-packages/django/core/management/base.py", line 460, in execute
    output = self.handle(*args, **options)
  File "/home/administrator/.local/lib/python3.10/site-packages/django/core/management/commands/runserver.py", line 110, in handle
    self.run(**options)
  File "/home/administrator/.local/lib/python3.10/site-packages/django/core/management/commands/runserver.py", line 117, in run
    autoreload.run_with_reloader(self.inner_run, **options)
  File "/home/administrator/.local/lib/python3.10/site-packages/django/utils/autoreload.py", line 670, in run_with_reloader
    start_django(reloader, main_func, *args, **kwargs)
  File "/home/administrator/.local/lib/python3.10/site-packages/django/utils/autoreload.py", line 659, in start_django
    reloader.run(django_main_thread)
  File "/home/administrator/.local/lib/python3.10/site-packages/django/utils/autoreload.py", line 342, in run
    autoreload_started.send(sender=self)
  File "/home/administrator/.local/lib/python3.10/site-packages/django/dispatch/dispatcher.py", line 189, in send
    response = receiver(signal=self, sender=sender, **named)
  File "/home/administrator/.local/lib/python3.10/site-packages/django/template/autoreload.py", line 50, in watch_for_template_changes
    for directory in get_template_directories():
  File "/home/administrator/.local/lib/python3.10/site-packages/django/template/autoreload.py", line 16, in get_template_directories
    for backend in engines.all():
  File "/home/administrator/.local/lib/python3.10/site-packages/django/template/utils.py", line 94, in all
    return [self[alias] for alias in self]
  File "/home/administrator/.local/lib/python3.10/site-packages/django/template/utils.py", line 94, in <listcomp>
    return [self[alias] for alias in self]
  File "/home/administrator/.local/lib/python3.10/site-packages/django/template/utils.py", line 85, in __getitem__
    engine = engine_cls(params)
  File "/home/administrator/.local/lib/python3.10/site-packages/django/template/backends/django.py", line 28, in __init__
    self.engine = Engine(self.dirs, self.app_dirs, **options)
  File "/home/administrator/.local/lib/python3.10/site-packages/django/template/engine.py", line 61, in __init__
    self.template_libraries = self.get_template_libraries(libraries)
  File "/home/administrator/.local/lib/python3.10/site-packages/django/template/engine.py", line 126, in get_template_libraries
    loaded[name] = import_library(path)
  File "/home/administrator/.local/lib/python3.10/site-packages/django/template/library.py", line 479, in import_library
    raise InvalidTemplateLibrary(
django.template.library.InvalidTemplateLibrary: Invalid template library specified. ImportError raised when trying to load 'templatetags.import_export_tags': No module named 'diff_match_patch'
